Workbook
Name BDelemento: 'Base de Datos'!$C$2:$C$119
Name BDnumeroAtomico: 'Base de Datos'!$D$2:$D$119
Name BDsimbolo: 'Base de Datos'!$B$2:$B$119

Sheet Fase 01
B3: UNIVERSIDAD RAFAEL LANDIVAR
B4: FACULTAD DE INGENIERÍA
B5: PRIMER SEMESTRE 2025
B6: QUÍMICA BÁSICA
B7: SECCION 02 (TEORÍA)
B8: INGRA. SYLVIA SABRINA MENDÍA REYES
C11: PROYECTO DEL CURSO
C12: FASE 01: TABLA PERIÓDICA Y CÁLCULO DE PROTONES, NEUTRONES Y ELECTRONES
E17: INTEGRANTES | H17: CARNET
E18: RUIZ COTO, JULIO ANTHONY ENGELS | H18: 1284719
E19: GIRÓN ZAMORA, JASON BRIAN | H19: 1135220
C25: Guatemala, 04 de mayo de 2025

Sheet Base de Datos
A1: id | B1: Simbolo | C1: Nombre del Elemento | D1: Numero Atomico | E1: Masa atomica | F1: Número de oxidación
A2: 1 | B2: H | C2: Hidrógeno | D2: 1 | E2: 1.008 | F2: +1
A3: 2 | B3: He | C3: Helio | D3: 2 | E3: 4.0026
A4: 3 | B4: Li | C4: Litio | D4: 3 | E4: 6.94 | F4: +1
A5: 4 | B5: Be | C5: Berilio | D5: 4 | E5: 9.0122 | F5: +2
A6: 5 | B6: B | C6: Boro | D6: 5 | E6: 10.81 | F6: ± 3
A7: 6 | B7: C | C7: Carbono | D7: 6 | E7: 12.011 | F7: +2, ± 4
A8: 7 | B8: N | C8: Nitrógeno | D8: 7 | E8: 14.007 | F8: ± 1 ± 2 ± 3 ± 4 ± 5
A9: 8 | B9: O | C9: Oxígeno | D9: 8 | E9: 15.999 | F9: -1 -2
A10: 9 | B10: F | C10: Flúor | D10: 9 | E10: 18.998 | F10: -1
A11: 10 | B11: Ne | C11: Neón | D11: 10 | E11: 20.18
A12: 11 | B12: Na | C12: Sodio | D12: 11 | E12: 22.99 | F12: +1
A13: 12 | B13: Mg | C13: Magnesio | D13: 12 | E13: 24.305 | F13: +2
A14: 13 | B14: Al | C14: Aluminio | D14: 13 | E14: 26.982 | F14: +3
A15: 14 | B15: Si | C15: Silicio | D15: 14 | E15: 28.085 | F15: +2, ± 4
A16: 15 | B16: P | C16: Fósforo | D16: 15 | E16: 30.974 | F16: ± 3, +5
A17: 16 | B17: S | C17: Azufre | D17: 16 | E17: 32.06 | F17: ± 2 +4 +6
A18: 17 | B18: Cl | C18: Cloro | D18: 17 | E18: 35.45 | F18: ± 1 +3 +5 +7
A19: 18 | B19: Ar | C19: Argón | D19: 18 | E19: 39.948
A20: 19 | B20: K | C20: Potasio | D20: 19 | E20: 39.098 | F20: +1
A21: 20 | B21: Ca | C21: Calcio | D21: 20 | E21: 40.078 | F21: +2
A22: 21 | B22: Sc | C22: Escandio | D22: 21 | E22: 44.956 | F22: +3
A23: 22 | B23: Ti | C23: Titanio | D23: 22 | E23: 47.867 | F23: +2 +3 +4
A24: 23 | B24: V | C24: Vanadio | D24: 23 | E24: 50.942 | F24: +2 +3 +4 +5
A25: 24 | B25: Cr | C25: Cromo | D25: 24 | E25: 51.996 | F25: +2 +3 +6
A26: 25 | B26: Mn | C26: Manganeso | D26: 25 | E26: 54.938 | F26: +2 +3 +4 +6 +7
A27: 26 | B27: Fe | C27: Hierro | D27: 26 | E27: 55.845 | F27: +2 +3
A28: 27 | B28: Co | C28: Cobalto | D28: 27 | E28: 58.933 | F28: +2 +3
A29: 28 | B29: Ni | C29: Níquel | D29: 28 | E29: 58.693 | F29: +2 +3
A30: 29 | B30: Cu | C30: Cobre | D30: 29 | E30: 63.546 | F30: +1 +2
A31: 30 | B31: Zn | C31: Zinc | D31: 30 | E31: 65.38 | F31: +2
... A36: 35 | B36: Br | C36: Bromo | D36: 35 | E36: 79.904 | F36: ± 1 +3 +5 +7
A37: 36 | B37: Kr | C37: Kriptón | D37: 36 | E37: 83.798
A38: 37 | B38: Rb | C38: Rubidio | D38: 37 | E38: 85.4678 | F38: +1
A39: 38 | B39: Sr | C39: Estroncio | D39: 38 | E39: 87.62 | F39: +2
A40: 39 | B40: Y | C40: Itrio | D40: 39 | E40: 88.9059 | F40: +3
A41: 40 | B41: Zr | C41: Circonio | D41: 40 | E41: 91.224 | F41: +3 +4
A42: 41 | B42: Nb | C42: Niobio | D42: 41 | E42: 92.9064 | F42: +2 +3 +4 +5
A43: 42 | B43: Mo | C43: Molibdeno | D43: 42 | E43: 95.94 | F43: +2 +3 +4 +5 +6
A44: 43 | B44: Tc | C44: Tecnecio | D44: 43 | E44: 98 | F44: +4 +5 +6 +7
...

Sheet Tabla Periodica
B2: 1 / IA | S2: 18 / VIIIA
B3: 1 | S3: 2
B4: =IF(VLOOKUP(B3,'Base de Datos'!$A$2:$F$119,6)=0,"",VLOOKUP(B3,'Base de Datos'!$A$2:$F$119,6)) -> +1 | S4: =IF(VLOOKUP(S3,'Base de Datos'!$A$2:$F$119,6)=0,"",VLOOKUP(S3,'Base de Datos'!$A$2:$F$119,6))
B5: =VLOOKUP(B3,'Base de Datos'!$A$2:$E$119,2) -> H | G5: ` | S5: =VLOOKUP(S3,'Base de Datos'!$A$2:$E$119,2) -> He
B7: =VLOOKUP(B3,'Base de Datos'!$A$2:$E$119,3) -> Hidrógeno | C7: 2 / IIA | N7: 13 / IIIA | O7: 14 / IVA | P7: 15 / VA | Q7: 16 / VIA | R7: 17 / VIIA | S7: =VLOOKUP(S3,'Base de Datos'!$A$2:$E$119,3) -> Helio
B8: 3 | C8: 4 | N8: 5 | O8: 6 | P8: 7 | Q8: 8 | R8: 9 | S8: 10
B9: =IF(VLOOKUP(B8,'Base de Datos'!$A$2:$F$119,6)=0,"",VLOOKUP(B8,'Base de Datos'!$A$2:$F$119,6)) -> +1 | C9: =IF(VLOOKUP(C8,'Base de Datos'!$A$2:$F$119,6)=0,"",VLOOKUP(C8,'Base de Datos'!$A$2:$F$119,6)) -> +2 | N9: =IF(VLOOKUP(N8,'Base de Datos'!$A$2:$F$119,6)=0,"",VLOOKUP(N8,'Base de Datos'!$A$2:$F$119,6)) -> ± 3 | O9: =IF(VLOOKUP(O8,'Base de Datos'!$A$2:$F$119,6)=0,"",VLOOKUP(O8,'Base de Datos'!$A$2:$F$119,6)) -> +2, ± 4 | P9: =IF(VLOOKUP(P8,'Base de Datos'!$A$2:$F$119,6)=0,"",VLOOKUP(P8,'Base de Datos'!$A$2:$F$119,6)) -> ± 1 ± 2 ± 3 ± 4 ± 5 | Q9: =IF(VLOOKUP(Q8,'Base de Datos'!$A$2:$F$119,6)=0,"",VLOOKUP(Q8,'Base de Datos'!$A$2:$F$119,6)) -> -1 -2 | R9: =IF(VLOOKUP(R8,'Base de Datos'!$A$2:$F$119,6)=0,"",VLOOKUP(R8,'Base de Datos'!$A$2:$F$119,6)) -> -1 | S9: =IF(VLOOKUP(S8,'Base de Datos'!$A$2:$F$119,6)=0,"",VLOOKUP(S8,'Base de Datos'!$A$2:$F$119,6))
B10: =VLOOKUP(B8,'Base de Datos'!$A$2:$E$119,2) -> Li | C10: =VLOOKUP(C8,'Base de Datos'!$A$2:$E$119,2) -> Be | N10: =VLOOKUP(N8,'Base de Datos'!$A$2:$E$119,2) -> B | O10: =VLOOKUP(O8,'Base de Datos'!$A$2:$E$119,2) -> C | P10: =VLOOKUP(P8,'Base de Datos'!$A$2:$E$119,2) -> N | Q10: =VLOOKUP(Q8,'Base de Datos'!$A$2:$E$119,2) -> O | R10: =VLOOKUP(R8,'Base de Datos'!$A$2:$E$119,2) -> F | S10: =VLOOKUP(S8,'Base de Datos'!$A$2:$E$119,2) -> Ne
B12: =VLOOKUP(B8,'Base de Datos'!$A$2:$E$119,3) -> Litio | C12: =VLOOKUP(C8,'Base de Datos'!$A$2:$E$119,3) -> Berilio | N12: =VLOOKUP(N8,'Base de Datos'!$A$2:$E$119,3) -> Boro | O12: =VLOOKUP(O8,'Base de Datos'!$A$2:$E$119,3) -> Carbono | P12: =VLOOKUP(P8,'Base de Datos'!$A$2:$E$119,3) -> Nitrógeno | Q12: =VLOOKUP(Q8,'Base de Datos'!$A$2:$E$119,3) -> Oxígeno | R12: =VLOOKUP(R8,'Base de Datos'!$A$2:$E$119,3) -> Flúor | S12: =VLOOKUP(S8,'Base de Datos'!$A$2:$E$119,3) -> Neón
B13: 11 | C13: 12 | N13: 13 | O13: 14 | P13: 15 | Q13: 16 | R13: 17 | S13: 18
B14: =IF(VLOOKUP(B13,'Base de Datos'!$A$2:$F$119,6)=0,"",VLOOKUP(B13,'Base de Datos'!$A$2:$F$119,6)) -> +1 | C14: =IF(VLOOKUP(C13,'Base de Datos'!$A$2:$F$119,6)=0,"",VLOOKUP(C13,'Base de Datos'!$A$2:$F$119,6)) -> +2 | N14: =IF(VLOOKUP(N13,'Base de Datos'!$A$2:$F$119,6)=0,"",VLOOKUP(N13,'Base de Datos'!$A$2:$F$119,6)) -> +3 | O14: =IF(VLOOKUP(O13,'Base de Datos'!$A$2:$F$119,6)=0,"",VLOOKUP(O13,'Base de Datos'!$A$2:$F$119,6)) -> +2, ± 4 | P14: =IF(VLOOKUP(P13,'Base de Datos'!$A$2:$F$119,6)=0,"",VLOOKUP(P13,'Base de Datos'!$A$2:$F$119,6)) -> ± 3, +5 | Q14: =IF(VLOOKUP(Q13,'Base de Datos'!$A$2:$F$119,6)=0,"",VLOOKUP(Q13,'Base de Datos'!$A$2:$F$119,6)) -> ± 2 +4 +6 | R14: =IF(VLOOKUP(R13,'Base de Datos'!$A$2:$F$119,6)=0,"",VLOOKUP(R13,'Base de Datos'!$A$2:$F$119,6)) -> ± 1 +3 +5 +7 | S14: =IF(VLOOKUP(S13,'Base de Datos'!$A$2:$F$119,6)=0,"",VLOOKUP(S13,'Base de Datos'!$A$2:$F$119,6))
B15: =VLOOKUP(B13,'Base de Datos'!$A$2:$E$119,2) -> Na | C15: =VLOOKUP(C13,'Base de Datos'!$A$2:$E$119,2) -> Mg | N15: =VLOOKUP(N13,'Base de Datos'!$A$2:$E$119,2) -> Al | O15: =VLOOKUP(O13,'Base de Datos'!$A$2:$E$119,2) -> Si | P15: =VLOOKUP(P13,'Base de Datos'!$A$2:$E$119,2) -> P | Q15: =VLOOKUP(Q13,'Base de Datos'!$A$2:$E$119,2) -> S | R15: =VLOOKUP(R13,'Base de Datos'!$A$2:$E$119,2) -> Cl | S15: =VLOOKUP(S13,'Base de Datos'!$A$2:$E$119,2) -> Ar
I16: VIIIB
B17: =VLOOKUP(B13,'Base de Datos'!$A$2:$E$119,3) -> Sodio | C17: =VLOOKUP(C13,'Base de Datos'!$A$2:$E$119,3) -> Magnesio | D17: 3 / IIIB | E17: 4 / IVB | F17: 5 / VB | G17: 6 / VIB | H17: 7 / VIIB | I17: 8 | J17: 9 | K17: 10 | L17: 11 / IB | M17: 12 / IIB | N17: =VLOOKUP(N13,'Base de Datos'!$A$2:$E$119,3) -> Aluminio | O17: =VLOOKUP(O13,'Base de Datos'!$A$2:$E$119,3) -> Silicio | P17: =VLOOKUP(P13,'Base de Datos'!$A$2:$E$119,3) -> Fósforo | Q17: =VLOOKUP(Q13,'Base de Datos'!$A$2:$E$119,3) -> Azufre | R17: =VLOOKUP(R13,'Base de Datos'!$A$2:$E$119,3) -> Cloro | S17: =VLOOKUP(S13,'Base de Datos'!$A$2:$E$119,3) -> Argón
B18: 19 | C18: 20 | D18: 21 | E18: 22 | F18: 23 | G18: 24 | H18: 25 | I18: 26 | J18: 27 | K18: 28 | L18: 29 | M18: 30 | N18: 31 | O18: 32 | P18: 33 | Q18: 34 | R18: 35 | S18: 36
B19: =IF(VLOOKUP(B18,'Base de Datos'!$A$2:$F$119,6)=0,"",VLOOKUP(B18,'Base de Datos'!$A$2:$F$119,6)) -> +1 | C19: =IF(VLOOKUP(C18,'Base de Datos'!$A$2:$F$119,6)=0,"",VLOOKUP(C18,'Base de Datos'!$A$2:$F$119,6)) -> +2 | D19: =IF(VLOOKUP(D18,'Base de Datos'!$A$2:$F$119,6)=0,"",VLOOKUP(D18,'Base de Datos'!$A$2:$F$119,6)) -> +3 | E19: =IF(VLOOKUP(E18,'Base de Datos'!$A$2:$F$119,6)=0,"",VLOOKUP(E18,'Base de Datos'!$A$2:$F$119,6)) -> +2 +3 +4 | F19: =IF(VLOOKUP(F18,'Base de Datos'!$A$2:$F$119,6)=0,"",VLOOKUP(F18,'Base de Datos'!$A$2:$F$119,6)) -> +2 +3 +4 +5 | G19: =IF(VLOOKUP(G18,'Base de Datos'!$A$2:$F$119,6)=0,"",VLOOKUP(G18,'Base de Datos'!$A$2:$F$119,6)) -> +2 +3 +6 | H19: =IF(VLOOKUP(H18,'Base de Datos'!$A$2:$F$119,6)=0,"",VLOOKUP(H18,'Base de Datos'!$A$2:$F$119,6)) -> +2 +3 +4 +6 +7 | I19: =IF(VLOOKUP(I18,'Base de Datos'!$A$2:$F$119,6)=0,"",VLOOKUP(I18,'Base de Datos'!$A$2:$F$119,6)) -> +2 +3 | ... S19: =IF(VLOOKUP(S18,'Base de Datos'!$A$2:$F$119,6)=0,"",VLOOKUP(S18,'Base de Datos'!$A$2:$F$119,6))
B20: =VLOOKUP(B18,'Base de Datos'!$A$2:$E$119,2) -> K | C20: =VLOOKUP(C18,'Base de Datos'!$A$2:$E$119,2) -> Ca | D20: =VLOOKUP(D18,'Base de Datos'!$A$2:$E$119,2) -> Sc | E20: =VLOOKUP(E18,'Base de Datos'!$A$2:$E$119,2) -> Ti | F20: =VLOOKUP(F18,'Base de Datos'!$A$2:$E$119,2) -> V | G20: =VLOOKUP(G18,'Base de Datos'!$A$2:$E$119,2) -> Cr | H20: =VLOOKUP(H18,'Base de Datos'!$A$2:$E$119,2) -> Mn | I20: =VLOOKUP(I18,'Base de Datos'!$A$2:$E$119,2) -> Fe | ... S20: =VLOOKUP(S18,'Base de Datos'!$A$2:$E$119,2) -> Kr
B22: =VLOOKUP(B18,'Base de Datos'!$A$2:$E$119,3) -> Potasio | C22: =VLOOKUP(C18,'Base de Datos'!$A$2:$E$119,3) -> Calcio | D22: =VLOOKUP(D18,'Base de Datos'!$A$2:$E$119,3) -> Escandio | E22: =VLOOKUP(E18,'Base de Datos'!$A$2:$E$119,3) -> Titanio | F22: =VLOOKUP(F18,'Base de Datos'!$A$2:$E$119,3) -> Vanadio | G22: =VLOOKUP(G18,'Base de Datos'!$A$2:$E$119,3) -> Cromo | H22: =VLOOKUP(H18,'Base de Datos'!$A$2:$E$119,3) -> Manganeso | I22: =VLOOKUP(I18,'Base de Datos'!$A$2:$E$119,3) -> Hierro | ... S22: =VLOOKUP(S18,'Base de Datos'!$A$2:$E$119,3) -> Kriptón
B23: 37 | C23: 38 | D23: 39 | E23: 40 | F23: 41 | G23: 42 | H23: 43 | I23: 44 | J23: 45 | K23: 46 | L23: 47 | M23: 48 | N23: 49 | O23: 50 | P23: 51 | Q23: 52 | R23: 53 | S23: 54
B24: =IF(VLOOKUP(B23,'Base de Datos'!$A$2:$F$119,6)=0,"",VLOOKUP(B23,'Base de Datos'!$A$2:$F$119,6)) -> +1 | C24: =IF(VLOOKUP(C23,'Base de Datos'!$A$2:$F$119,6)=0,"",VLOOKUP(C23,'Base de Datos'!$A$2:$F$119,6)) -> +2 | D24: =IF(VLOOKUP(D23,'Base de Datos'!$A$2:$F$119,6)=0,"",VLOOKUP(D23,'Base de Datos'!$A$2:$F$119,6)) -> +3 | E24: =IF(VLOOKUP(E23,'Base de Datos'!$A$2:$F$119,6)=0,"",VLOOKUP(E23,'Base de Datos'!$A$2:$F$119,6)) -> +3 +4 | F24: =IF(VLOOKUP(F23,'Base de Datos'!$A$2:$F$119,6)=0,"",VLOOKUP(F23,'Base de Datos'!$A$2:$F$119,6)) -> +2 +3 +4 +5 | G24: =IF(VLOOKUP(G23,'Base de Datos'!$A$2:$F$119,6)=0,"",VLOOKUP(G23,'Base de Datos'!$A$2:$F$119,6)) -> +2 +3 +4 +5 +6 | H24: =IF(VLOOKUP(H23,'Base de Datos'!$A$2:$F$119,6)=0,"",VLOOKUP(H23,'Base de Datos'!$A$2:$F$119,6)) -> +4 +5 +6 +7 | I24: =IF(VLOOKUP(I23,'Base de Datos'!$A$2:$F$119,6)=0,"",VLOOKUP(I23,'Base de Datos'!$A$2:$F$119,6)) -> +2 +3 +4 +5 +6 +7 +8 | ... S24: =IF(VLOOKUP(S23,'Base de Datos'!$A$2:$F$119,6)=0,"",VLOOKUP(S23,'Base de Datos'!$A$2:$F$119,6))
B25: =VLOOKUP(B23,'Base de Datos'!$A$2:$E$119,2) -> Rb | C25: =VLOOKUP(C23,'Base de Datos'!$A$2:$E$119,2) -> Sr | D25: =VLOOKUP(D23,'Base de Datos'!$A$2:$E$119,2) -> Y | E25: =VLOOKUP(E23,'Base de Datos'!$A$2:$E$119,2) -> Zr | F25: =VLOOKUP(F23,'Base de Datos'!$A$2:$E$119,2) -> Nb | G25: =VLOOKUP(G23,'Base de Datos'!$A$2:$E$119,2) -> Mo | H25: =VLOOKUP(H23,'Base de Datos'!$A$2:$E$119,2) -> Tc | I25: =VLOOKUP(I23,'Base de Datos'!$A$2:$E$119,2) -> Ru | ... S25: =VLOOKUP(S23,'Base de Datos'!$A$2:$E$119,2) -> Xe
B27: =VLOOKUP(B23,'Base de Datos'!$A$2:$E$119,3) -> Rubidio | C27: =VLOOKUP(C23,'Base de Datos'!$A$2:$E$119,3) -> Estroncio | D27: =VLOOKUP(D23,'Base de Datos'!$A$2:$E$119,3) -> Itrio | E27: =VLOOKUP(E23,'Base de Datos'!$A$2:$E$119,3) -> Circonio | F27: =VLOOKUP(F23,'Base de Datos'!$A$2:$E$119,3) -> Niobio | G27: =VLOOKUP(G23,'Base de Datos'!$A$2:$E$119,3) -> Molibdeno | H27: =VLOOKUP(H23,'Base de Datos'!$A$2:$E$119,3) -> Tecnecio | I27: =VLOOKUP(I23,'Base de Datos'!$A$2:$E$119,3) -> Rutenio | ... S27: =VLOOKUP(S23,'Base de Datos'!$A$2:$E$119,3) -> Xenón
B28: 55 | C28: 56 | D28: 57 al 71 | E28: 72 | F28: 73 | G28: 74 | H28: 75 | I28: 76 | J28: 77 | K28: 78 | L28: 79 | M28: 80 | N28: 81 | O28: 82 | P28: 83 | Q28: 84 | R28: 85 | S28: 86
B29: =IF(VLOOKUP(B28,'Base de Datos'!$A$2:$F$119,6)=0,"",VLOOKUP(B28,'Base de Datos'!$A$2:$F$119,6)) -> +1 | C29: =IF(VLOOKUP(C28,'Base de Datos'!$A$2:$F$119,6)=0,"",VLOOKUP(C28,'Base de Datos'!$A$2:$F$119,6)) -> +2 | E29: =IF(VLOOKUP(E28,'Base de Datos'!$A$2:$F$119,6)=0,"",VLOOKUP(E28,'Base de Datos'!$A$2:$F$119,6)) -> +3 +4 | F29: =IF(VLOOKUP(F28,'Base de Datos'!$A$2:$F$119,6)=0,"",VLOOKUP(F28,'Base de Datos'!$A$2:$F$119,6)) -> +3 +4 +5 | G29: =IF(VLOOKUP(G28,'Base de Datos'!$A$2:$F$119,6)=0,"",VLOOKUP(G28,'Base de Datos'!$A$2:$F$119,6)) -> +2 +3 +4 +5 +6 | H29: =IF(VLOOKUP(H28,'Base de Datos'!$A$2:$F$119,6)=0,"",VLOOKUP(H28,'Base de Datos'!$A$2:$F$119,6)) -> +2 +3 +4 +6 +7 | I29: =IF(VLOOKUP(I28,'Base de Datos'!$A$2:$F$119,6)=0,"",VLOOKUP(I28,'Base de Datos'!$A$2:$F$119,6)) -> +2 +3 +4 +5 +6 +7 +8 | J29: =IF(VLOOKUP(J28,'Base de Datos'!$A$2:$F$119,6)=0,"",VLOOKUP(J28,'Base de Datos'!$A$2:$F$119,6)) -> +2 +3 +4 +5 +6 | K29: =IF(VLOOKUP(K28,'Base de Datos'!$A$2:$F$119,6)=0,"",VLOOKUP(K28,'Base de Datos'!$A$2:$F$119,6)) -> +2 +4 | L29: =IF(VLOOKUP(L28,'Base de Datos'!$A$2:$F$119,6)=0,"",VLOOKUP(L28,'Base de Datos'!$A$2:$F$119,6)) -> +1 +3 | ... S29: =IF(VLOOKUP(S28,'Base de Datos'!$A$2:$F$119,6)=0,"",VLOOKUP(S28,'Base de Datos'!$A$2:$F$119,6))
B30: =VLOOKUP(B28,'Base de Datos'!$A$2:$E$119,2) -> Cs | C30: =VLOOKUP(C28,'Base de Datos'!$A$2:$E$119,2) -> Ba | E30: =VLOOKUP(E28,'Base de Datos'!$A$2:$E$119,2) -> Hf | F30: =VLOOKUP(F28,'Base de Datos'!$A$2:$E$119,2) -> Ta | G30: =VLOOKUP(G28,'Base de Datos'!$A$2:$E$119,2) -> W | H30: =VLOOKUP(H28,'Base de Datos'!$A$2:$E$119,2) -> Re | I30: =VLOOKUP(I28,'Base de Datos'!$A$2:$E$119,2) -> Os | J30: =VLOOKUP(J28,'Base de Datos'!$A$2:$E$119,2) -> Ir | K30: =VLOOKUP(K28,'Base de Datos'!$A$2:$E$119,2) -> Pt | L30: =VLOOKUP(L28,'Base de Datos'!$A$2:$E$119,2) -> Au | ... S30: =VLOOKUP(S28,'Base de Datos'!$A$2:$E$119,2) -> Rn
B32: =VLOOKUP(B28,'Base de Datos'!$A$2:$E$119,3) -> Cesio | C32: =VLOOKUP(C28,'Base de Datos'!$A$2:$E$119,3) -> Bario | E32: =VLOOKUP(E28,'Base de Datos'!$A$2:$E$119,3) -> Hafnio | F32: =VLOOKUP(F28,'Base de Datos'!$A$2:$E$119,3) -> Tántalo | G32: =VLOOKUP(G28,'Base de Datos'!$A$2:$E$119,3) -> Tungsteno | H32: =VLOOKUP(H28,'Base de Datos'!$A$2:$E$119,3) -> Renio | I32: =VLOOKUP(I28,'Base de Datos'!$A$2:$E$119,3) -> Osmio | J32: =VLOOKUP(J28,'Base de Datos'!$A$2:$E$119,3) -> Iridio | K32: =VLOOKUP(K28,'Base de Datos'!$A$2:$E$119,3) -> Platino | L32: =VLOOKUP(L28,'Base de Datos'!$A$2:$E$119,3) -> Oro | ... S32: =VLOOKUP(S28,'Base de Datos'!$A$2:$E$119,3) -> Radón
B33: 87 | C33: 88 | D33: 89 al 103 | E33: 104 | F33: 105 | G33: 106 | H33: 107 | I33: 108 | J33: 109 | K33: 110 | L33: 111 | M33: 112 | N33: 113 | O33: 114 | P33: 115 | Q33: 116 | R33: 117 | S33: 118
B34: =IF(VLOOKUP(B33,'Base de Datos'!$A$2:$F$119,6)=0,"",VLOOKUP(B33,'Base de Datos'!$A$2:$F$119,6)) -> +1 | C34: =IF(VLOOKUP(C33,'Base de Datos'!$A$2:$F$119,6)=0,"",VLOOKUP(C33,'Base de Datos'!$A$2:$F$119,6)) -> +2 | E34: =IF(VLOOKUP(E33,'Base de Datos'!$A$2:$F$119,6)=0,"",VLOOKUP(E33,'Base de Datos'!$A$2:$F$119,6)) -> +3 +4 | F34: =IF(VLOOKUP(F33,'Base de Datos'!$A$2:$F$119,6)=0,"",VLOOKUP(F33,'Base de Datos'!$A$2:$F$119,6)) | G34: =IF(VLOOKUP(G33,'Base de Datos'!$A$2:$F$119,6)=0,"",VLOOKUP(G33,'Base de Datos'!$A$2:$F$119,6)) | H34: =IF(VLOOKUP(H33,'Base de Datos'!$A$2:$F$119,6)=0,"",VLOOKUP(H33,'Base de Datos'!$A$2:$F$119,6)) | I34: =IF(VLOOKUP(I33,'Base de Datos'!$A$2:$F$119,6)=0,"",VLOOKUP(I33,'Base de Datos'!$A$2:$F$119,6)) | J34: =IF(VLOOKUP(J33,'Base de Datos'!$A$2:$F$119,6)=0,"",VLOOKUP(J33,'Base de Datos'!$A$2:$F$119,6)) | K34: =IF(VLOOKUP(K33,'Base de Datos'!$A$2:$F$119,6)=0,"",VLOOKUP(K33,'Base de Datos'!$A$2:$F$119,6)) | L34: =IF(VLOOKUP(L33,'Base de Datos'!$A$2:$F$119,6)=0,"",VLOOKUP(L33,'Base de Datos'!$A$2:$F$119,6)) | ... S34: =IF(VLOOKUP(S33,'Base de Datos'!$A$2:$F$119,6)=0,"",VLOOKUP(S33,'Base de Datos'!$A$2:$F$119,6))
B35: =VLOOKUP(B33,'Base de Datos'!$A$2:$E$119,2) -> Fr | C35: =VLOOKUP(C33,'Base de Datos'!$A$2:$E$119,2) -> Ra | E35: =VLOOKUP(E33,'Base de Datos'!$A$2:$E$119,2) -> Rf | F35: =VLOOKUP(F33,'Base de Datos'!$A$2:$E$119,2) -> Db | G35: =VLOOKUP(G33,'Base de Datos'!$A$2:$E$119,2) -> Sg | H35: =VLOOKUP(H33,'Base de Datos'!$A$2:$E$119,2) -> Bh | I35: =VLOOKUP(I33,'Base de Datos'!$A$2:$E$119,2) -> Hs | J35: =VLOOKUP(J33,'Base de Datos'!$A$2:$E$119,2) -> Mt | K35: =VLOOKUP(K33,'Base de Datos'!$A$2:$E$119,2) -> Ds | L35: =VLOOKUP(L33,'Base de Datos'!$A$2:$E$119,2) -> Rg | ... S35: =VLOOKUP(S33,'Base de Datos'!$A$2:$E$119,2) -> Og
B37: =VLOOKUP(B33,'Base de Datos'!$A$2:$E$119,3) -> Francio | C37: =VLOOKUP(C33,'Base de Datos'!$A$2:$E$119,3) -> Radio | E37: =VLOOKUP(E33,'Base de Datos'!$A$2:$E$119,3) -> Rutherfordio | F37: =VLOOKUP(F33,'Base de Datos'!$A$2:$E$119,3) -> Dubnio | G37: =VLOOKUP(G33,'Base de Datos'!$A$2:$E$119,3) -> Seaborgio | H37: =VLOOKUP(H33,'Base de Datos'!$A$2:$E$119,3) -> Bohrio | I37: =VLOOKUP(I33,'Base de Datos'!$A$2:$E$119,3) -> Hassio | J37: =VLOOKUP(J33,'Base de Datos'!$A$2:$E$119,3) -> Meitnerio | K37: =VLOOKUP(K33,'Base de Datos'!$A$2:$E$119,3) -> Darmstadtio | L37: =VLOOKUP(L33,'Base de Datos'!$A$2:$E$119,3) -> Roentgenio | ... S37: =VLOOKUP(S33,'Base de Datos'!$A$2:$E$119,3) -> Oganesón
E39: 57 | F39: 58 | G39: 59 | H39: 60 | I39: 61 | J39: 62 | K39: 63 | L39: 64 | M39: 65 | N39: 66 | O39: 67 | P39: 68 | Q39: 69 | R39: 70 | S39: 71
E40: =IF(VLOOKUP(E39,'Base de Datos'!$A$2:$F$119,6)=0,"",VLOOKUP(E39,'Base de Datos'!$A$2:$F$119,6)) -> +3 | F40: =IF(VLOOKUP(F39,'Base de Datos'!$A$2:$F$119,6)=0,"",VLOOKUP(F39,'Base de Datos'!$A$2:$F$119,6)) -> +3 +4 | G40: =IF(VLOOKUP(G39,'Base de Datos'!$A$2:$F$119,6)=0,"",VLOOKUP(G39,'Base de Datos'!$A$2:$F$119,6)) -> +3 +4 +5 | H40: =IF(VLOOKUP(H39,'Base de Datos'!$A$2:$F$119,6)=0,"",VLOOKUP(H39,'Base de Datos'!$A$2:$F$119,6)) | I40: =IF(VLOOKUP(I39,'Base de Datos'!$A$2:$F$119,6)=0,"",VLOOKUP(I39,'Base de Datos'!$A$2:$F$119,6)) | J40: =IF(VLOOKUP(J39,'Base de Datos'!$A$2:$F$119,6)=0,"",VLOOKUP(J39,'Base de Datos'!$A$2:$F$119,6)) | K40: =IF(VLOOKUP(K39,'Base de Datos'!$A$2:$F$119,6)=0,"",VLOOKUP(K39,'Base de Datos'!$A$2:$F$119,6)) | L40: =IF(VLOOKUP(L39,'Base de Datos'!$A$2:$F$119,6)=0,"",VLOOKUP(L39,'Base de Datos'!$A$2:$F$119,6)) | ... S40: =IF(VLOOKUP(S39,'Base de Datos'!$A$2:$F$119,6)=0,"",VLOOKUP(S39,'Base de Datos'!$A$2:$F$119,6))
E41: =VLOOKUP(E39,'Base de Datos'!$A$2:$E$119,2) -> La | F41: =VLOOKUP(F39,'Base de Datos'!$A$2:$E$119,2) -> Ce | G41: =VLOOKUP(G39,'Base de Datos'!$A$2:$E$119,2) -> Pr | H41: =VLOOKUP(H39,'Base de Datos'!$A$2:$E$119,2) -> Nd | I41: =VLOOKUP(I39,'Base de Datos'!$A$2:$E$119,2) -> Pm | J41: =VLOOKUP(J39,'Base de Datos'!$A$2:$E$119,2) -> Sm | K41: =VLOOKUP(K39,'Base de Datos'!$A$2:$E$119,2) -> Eu | L41: =VLOOKUP(L39,'Base de Datos'!$A$2:$E$119,2) -> Gd | ... S41: =VLOOKUP(S39,'Base de Datos'!$A$2:$E$119,2) -> Lu
E43: =VLOOKUP(E39,'Base de Datos'!$A$2:$E$119,3) -> Lantano | F43: =VLOOKUP(F39,'Base de Datos'!$A$2:$E$119,3) -> Cerio | G43: =VLOOKUP(G39,'Base de Datos'!$A$2:$E$119,3) -> Praseodimio | H43: =VLOOKUP(H39,'Base de Datos'!$A$2:$E$119,3) -> Neodimio | I43: =VLOOKUP(I39,'Base de Datos'!$A$2:$E$119,3) -> Prometio | J43: =VLOOKUP(J39,'Base de Datos'!$A$2:$E$119,3) -> Samario | K43: =VLOOKUP(K39,'Base de Datos'!$A$2:$E$119,3) -> Europio | L43: =VLOOKUP(L39,'Base de Datos'!$A$2:$E$119,3) -> Gadolinio | ... S43: =VLOOKUP(S39,'Base de Datos'!$A$2:$E$119,3) -> Lutecio
E44: 89 | F44: 90 | G44: 91 | H44: 92 | I44: 93 | J44: 94 | K44: 95 | L44: 96 | M44: 97 | N44: 98 | O44: 99 | P44: 100 | Q44: 101 | R44: 102 | S44: 103
E45: =IF(VLOOKUP(E44,'Base de Datos'!$A$2:$F$119,6)=0,"",VLOOKUP(E44,'Base de Datos'!$A$2:$F$119,6)) -> +3 | F45: =IF(VLOOKUP(F44,'Base de Datos'!$A$2:$F$119,6)=0,"",VLOOKUP(F44,'Base de Datos'!$A$2:$F$119,6)) | G45: =IF(VLOOKUP(G44,'Base de Datos'!$A$2:$F$119,6)=0,"",VLOOKUP(G44,'Base de Datos'!$A$2:$F$119,6)) | H45: =IF(VLOOKUP(H44,'Base de Datos'!$A$2:$F$119,6)=0,"",VLOOKUP(H44,'Base de Datos'!$A$2:$F$119,6)) | I45: =IF(VLOOKUP(I44,'Base de Datos'!$A$2:$F$119,6)=0,"",VLOOKUP(I44,'Base de Datos'!$A$2:$F$119,6)) | J45: =IF(VLOOKUP(J44,'Base de Datos'!$A$2:$F$119,6)=0,"",VLOOKUP(J44,'Base de Datos'!$A$2:$F$119,6)) | K45: =IF(VLOOKUP(K44,'Base de Datos'!$A$2:$F$119,6)=0,"",VLOOKUP(K44,'Base de Datos'!$A$2:$F$119,6)) | L45: =IF(VLOOKUP(L44,'Base de Datos'!$A$2:$F$119,6)=0,"",VLOOKUP(L44,'Base de Datos'!$A$2:$F$119,6)) | ... S45: =IF(VLOOKUP(S44,'Base de Datos'!$A$2:$F$119,6)=0,"",VLOOKUP(S44,'Base de Datos'!$A$2:$F$119,6))
E46: =VLOOKUP(E44,'Base de Datos'!$A$2:$E$119,2) -> Ac | F46: =VLOOKUP(F44,'Base de Datos'!$A$2:$E$119,2) -> Th | G46: =VLOOKUP(G44,'Base de Datos'!$A$2:$E$119,2) -> Pa | H46: =VLOOKUP(H44,'Base de Datos'!$A$2:$E$119,2) -> U | I46: =VLOOKUP(I44,'Base de Datos'!$A$2:$E$119,2) -> Np | J46: =VLOOKUP(J44,'Base de Datos'!$A$2:$E$119,2) -> Pu | K46: =VLOOKUP(K44,'Base de Datos'!$A$2:$E$119,2) -> Am | L46: =VLOOKUP(L44,'Base de Datos'!$A$2:$E$119,2) -> Cm | ... S46: =VLOOKUP(S44,'Base de Datos'!$A$2:$E$119,2) -> Lr
E48: =VLOOKUP(E44,'Base de Datos'!$A$2:$E$119,3) -> Actinio | F48: =VLOOKUP(F44,'Base de Datos'!$A$2:$E$119,3) -> Torio | G48: =VLOOKUP(G44,'Base de Datos'!$A$2:$E$119,3) -> Protactinio | H48: =VLOOKUP(H44,'Base de Datos'!$A$2:$E$119,3) -> Uranio | I48: =VLOOKUP(I44,'Base de Datos'!$A$2:$E$119,3) -> Neptunio | J48: =VLOOKUP(J44,'Base de Datos'!$A$2:$E$119,3) -> Plutonio | K48: =VLOOKUP(K44,'Base de Datos'!$A$2:$E$119,3) -> Americio | L48: =VLOOKUP(L44,'Base de Datos'!$A$2:$E$119,3) -> Curio | ... S48: =VLOOKUP(S44,'Base de Datos'!$A$2:$E$119,3) -> Lawrencio

Sheet Calculadora propiedades
D3: Calculadora Propiedades de los átomos
E6: Nombre / Símbolo elemento:
E7: Ca
E9: Número de masa (A):
E10: 40
E12: Carga del átomo (Q)
E13: 2
E15: =IF(E7="","Debes de ingresar todos los campos",IF(E17="","El elemento ingresado no existe o se escribió de forma incorrecta","Elemento identificado")) -> Elemento identificado
E16: =IF(E17="","","SíMBOLO") -> SíMBOLO | F16: =IF(E17="","","ELEMENTO") -> ELEMENTO
E17: =IFERROR(IFERROR(INDEX(BDsimbolo,MATCH(E7,BDsimbolo,0)),INDEX(BDsimbolo,MATCH(E7,BDelemento,0))),"") -> Ca | F17: =IFERROR(IFERROR(INDEX(BDelemento,MATCH(E7,BDsimbolo,0)),INDEX(BDelemento,MATCH(E7,BDelemento,0))),"") -> Calcio
E18: Protones | F18: =IF(E7="","Datos incompletos",IFERROR(IFERROR(INDEX(BDnumeroAtomico,MATCH(E7,BDsimbolo,0)),INDEX(BDnumeroAtomico,MATCH(E7,BDelemento,0))),"")) -> 20
E19: Neutrones | F19: =IF(E10="","Datos Incompleto (A)",IF(E17="","",ROUND(E10,0)-F18)) -> 20
E20: Electrones | F20: =IF(E13="","Datos incompletos(Q)",IF(E17="","",-(E13-F18))) -> 18

Sheet MarcoTeorico

Sheet Instructivo para el Usuario
